<robot name="robot">
  <link name="frame_assembly">
    <inertial>
      <origin xyz="0 0 0" rpy="0 0 0"/>
      <mass value="30"/>
      <inertia ixx="1" ixy="0" ixz="0" iyy="1" iyz="0" izz="1"/>
    </inertial>
    <visual>
      <origin xyz="2.77556e-17 -0.2921 -1.38778e-17" rpy="6.82962e-17 6.82962e-17 0"/>
      <geometry>
        <mesh filename="file://$(find startup)/urdf/robot/assets/frame__length_0_40640000000000004_meter.stl"/>
      </geometry>
      <material name="frame__length_0_40640000000000004_meter_material">
        <color rgba="0.647059 0.647059 0.647059 1"/>
      </material>
    </visual>
    <collision>
      <origin xyz="2.77556e-17 -0.2921 -1.38778e-17" rpy="6.82962e-17 6.82962e-17 0"/>
      <geometry>
        <mesh filename="file://$(find startup)/urdf/robot/assets/frame__length_0_40640000000000004_meter.stl"/>
      </geometry>
    </collision>
    <visual>
      <origin xyz="2.77556e-17 0.2921 -1.38778e-17" rpy="6.82962e-17 6.82962e-17 0"/>
      <geometry>
        <mesh filename="file://$(find startup)/urdf/robot/assets/frame__length_0_40640000000000004_meter.stl"/>
      </geometry>
      <material name="frame_2m_material">
        <color rgba="0.647059 0.647059 0.647059 1"/>
      </material>
    </visual>
    <collision>
      <origin xyz="2.77556e-17 0.2921 -1.38778e-17" rpy="6.82962e-17 6.82962e-17 0"/>
      <geometry>
        <mesh filename="file://$(find startup)/urdf/robot/assets/frame__length_0_40640000000000004_meter.stl"/>
      </geometry>
    </collision>
    <visual>
      <origin xyz="0 0 0" rpy="0 -0 0"/>
      <geometry>
        <mesh filename="file://$(find startup)/urdf/robot/assets/frame__length_0_40640000000000004_meter.stl"/>
      </geometry>
      <material name="frame__length_0_40640000000000004_meter_3_material">
        <color rgba="0.647059 0.647059 0.647059 1"/>
      </material>
    </visual>
    <collision>
      <origin xyz="0 0 0" rpy="0 -0 0"/>
      <geometry>
        <mesh filename="file://$(find startup)/urdf/robot/assets/frame__length_0_40640000000000004_meter.stl"/>
      </geometry>
    </collision>
    <visual>
      <origin xyz="0.2159 1.1189e-16 -2.1684e-18" rpy="6.82962e-17 -0 -1.5708"/>
      <geometry>
        <mesh filename="file://$(find startup)/urdf/robot/assets/frame__length_0_6096_meter.stl"/>
      </geometry>
      <material name="frame__length_0_6096_meter_material">
        <color rgba="0.647059 0.647059 0.647059 1"/>
      </material>
    </visual>
    <collision>
      <origin xyz="0.2159 1.1189e-16 -2.1684e-18" rpy="6.82962e-17 -0 -1.5708"/>
      <geometry>
        <mesh filename="file://$(find startup)/urdf/robot/assets/frame__length_0_6096_meter.stl"/>
      </geometry>
    </collision>
    <visual>
      <origin xyz="-0.2159 -1.09987e-16 -2.18865e-18" rpy="6.82962e-17 -0 1.5708"/>
      <geometry>
        <mesh filename="file://$(find startup)/urdf/robot/assets/frame__length_0_6096_meter.stl"/>
      </geometry>
      <material name="frame__length_0_6096_meter_2_material">
        <color rgba="0.647059 0.647059 0.647059 1"/>
      </material>
    </visual>
    <collision>
      <origin xyz="-0.2159 -1.09987e-16 -2.18865e-18" rpy="6.82962e-17 -0 1.5708"/>
      <geometry>
        <mesh filename="file://$(find startup)/urdf/robot/assets/frame__length_0_6096_meter.stl"/>
      </geometry>
    </collision>
  </link>

  <link name="front_left_wheel">
    <inertial>
      <origin xyz="0 0 0" rpy="0 0 0"/>
      <mass value="1.7"/>
      <inertia ixx="1" ixy="0" ixz="0" iyy="1" iyz="0" izz="1"/>
    </inertial>
    <visual>
      <origin xyz="0 1.38778e-17 -0.0396875" rpy="1.5708 1.5708 0"/>
      <geometry>
        <mesh filename="file://$(find startup)/urdf/robot/assets/wheel.stl"/>
      </geometry>
      <material name="wheel_material">
        <color rgba="0.231373 0.380392 0.705882 1"/>
      </material>
    </visual>
    <collision>
      <origin xyz="0 1.38778e-17 -0.0396875" rpy="1.5708 1.5708 0"/>
      <geometry>
        <mesh filename="file://$(find startup)/urdf/robot/assets/wheel.stl"/>
      </geometry>
    </collision>
  </link>
  <joint name="front_left_wheel_joint" type="continuous">
    <origin xyz="0.23495 -0.2159 0.04445" rpy="-1.5708 -0 1.5708"/>
    <parent link="frame_assembly"/>
    <child link="front_left_wheel"/>
    <axis xyz="0 0 -1"/>
    <limit effort="10" velocity="10"/>
    <dynamics damping="30.0" friction="50.0"/>
  </joint>

  <link name="rear_left_wheel">
    <inertial>
      <origin xyz="0 0 0" rpy="0 0 0"/>
      <mass value="1.7"/>
      <inertia ixx="1" ixy="0" ixz="0" iyy="1" iyz="0" izz="1"/>
    </inertial>
    <visual>
      <origin xyz="0 1.38778e-17 -0.0396875" rpy="1.5708 1.5708 0"/>
      <geometry>
        <mesh filename="file://$(find startup)/urdf/robot/assets/wheel.stl"/>
      </geometry>
      <material name="rear_left_wheel_material">
        <color rgba="0.231373 0.380392 0.705882 1"/>
      </material>
    </visual>
    <collision>
      <origin xyz="0 1.38778e-17 -0.0396875" rpy="1.5708 1.5708 0"/>
      <geometry>
        <mesh filename="file://$(find startup)/urdf/robot/assets/wheel.stl"/>
      </geometry>
    </collision>
  </link>
  <joint name="rear_left_wheel_joint" type="continuous">
    <origin xyz="0.23495 0.2159 0.0508" rpy="-1.5708 -0 1.5708"/>
    <parent link="frame_assembly"/>
    <child link="rear_left_wheel"/>
    <axis xyz="0 0 -1"/>
    <limit effort="10" velocity="10"/>
    <dynamics damping="30.0" friction="50.0"/>
  </joint>

  <link name="rear_right_wheel">
    <inertial>
      <origin xyz="0 0 0" rpy="0 0 0"/>
      <mass value="1.7"/>
      <inertia ixx="1" ixy="0" ixz="0" iyy="1" iyz="0" izz="1"/>
    </inertial>
    <visual>
      <origin xyz="0 -1.38778e-17 -0.0396875" rpy="-1.5708 -1.5708 0"/>
      <geometry>
        <mesh filename="file://$(find startup)/urdf/robot/assets/wheel.stl"/>
      </geometry>
      <material name="rear_right_wheel_material">
        <color rgba="0.231373 0.380392 0.705882 1"/>
      </material>
    </visual>
    <collision>
      <origin xyz="0 -1.38778e-17 -0.0396875" rpy="-1.5708 -1.5708 0"/>
      <geometry>
        <mesh filename="file://$(find startup)/urdf/robot/assets/wheel.stl"/>
      </geometry>
    </collision>
  </link>
  <joint name="rear_right_wheel_joint" type="continuous">
    <origin xyz="-0.23495 0.2159 0.0508" rpy="-1.5708 -0 -1.5708"/>
    <parent link="frame_assembly"/>
    <child link="rear_right_wheel"/>
    <axis xyz="0 0 1"/>
    <limit effort="10" velocity="10"/>
    <dynamics damping="30.0" friction="50.0"/>
  </joint>

  <link name="front_right_wheel">
    <inertial>
      <origin xyz="0 0 0" rpy="0 0 0"/>
      <mass value="1.7"/>
      <inertia ixx="1" ixy="0" ixz="0" iyy="1" iyz="0" izz="1"/>
    </inertial>
    <visual>
      <origin xyz="0 -1.38778e-17 -0.0396875" rpy="-1.5708 -1.5708 0"/>
      <geometry>
        <mesh filename="file://$(find startup)/urdf/robot/assets/wheel.stl"/>
      </geometry>
      <material name="front_right_wheel_material">
        <color rgba="0.231373 0.380392 0.705882 1"/>
      </material>
    </visual>
    <collision>
      <origin xyz="0 -1.38778e-17 -0.0396875" rpy="-1.5708 -1.5708 0"/>
      <geometry>
        <mesh filename="file://$(find startup)/urdf/robot/assets/wheel.stl"/>
      </geometry>
    </collision>
  </link>
  <joint name="front_right_wheel_joint" type="continuous">
    <origin xyz="-0.23495 -0.2159 0.0508" rpy="-1.5708 -0 -1.5708"/>
    <parent link="frame_assembly"/>
    <child link="front_right_wheel"/>
    <axis xyz="0 0 1"/>
    <limit effort="10" velocity="10"/>
    <dynamics damping="30.0" friction="50.0"/>
  </joint>

  <link name="front_arm">
    <inertial>
      <origin xyz="0 0 0" rpy="0 0 0"/>
      <mass value="1"/>
      <inertia ixx="1" ixy="0" ixz="0" iyy="1" iyz="0" izz="1"/>
    </inertial>
    <visual>
      <origin xyz="0.173037 0 -1.73472e-18" rpy="-1.5708 -1.66039e-32 1.48742e-17"/>
      <geometry>
        <mesh filename="file://$(find startup)/urdf/robot/assets/frame__length_0_40640000000000004_meter.stl"/>
      </geometry>
      <material name="frame__length_0_40640000000000004_meter_4_material">
        <color rgba="0.647059 0.647059 0.647059 1"/>
      </material>
    </visual>
    <collision>
      <origin xyz="0.173037 0 -1.73472e-18" rpy="-1.5708 -1.66039e-32 1.48742e-17"/>
      <geometry>
        <mesh filename="file://$(find startup)/urdf/robot/assets/frame__length_0_40640000000000004_meter.stl"/>
      </geometry>
    </collision>
  </link>
  
  <joint name="front_arm_joint" type="continuous">
    <origin xyz="3.1225e-17 -0.2921 0.0508" rpy="-1.5708 -1.0472 -1.5708"/>
    <parent link="frame_assembly"/>
    <child link="front_arm"/>
    <axis xyz="0 0 -1"/>
    <limit effort="1000" velocity="1000"/>
    <!-- <limit effort="1000" velocity="1000" lower="-2" upper="0.4"/> -->
    <dynamics damping="80.0" friction="700.0" armature="0.01" />
  </joint>

  <link name="drum">
    <inertial>
      <origin xyz="0 0 0" rpy="0 0 0"/>
      <mass value="1"/>
      <inertia ixx="1" ixy="0" ixz="0" iyy="1" iyz="0" izz="1"/>
    </inertial>
    <visual>
      <origin xyz="0 0 0.00254" rpy="-1.5708 -1.57526e-32 4.0637e-17"/>
      <geometry>
        <mesh filename="file://$(find startup)/urdf/robot/assets/drum.stl"/>
      </geometry>
      <material name="drum_material">
        <color rgba="0.85098 0.756863 0.866667 1"/>
      </material>
    </visual>
    <collision>
      <origin xyz="0 0 0.00254" rpy="-1.5708 -1.57526e-32 4.0637e-17"/>
      <geometry>
        <mesh filename="file://$(find startup)/urdf/robot/assets/drum.stl"/>
      </geometry>
    </collision>
  </link>
  <joint name="front_left_drum_joint" type="continuous">
    <origin xyz="0.357187 0.0476885 0.0381" rpy="1.51327e-16 -1.41588e-16 -1.5708"/>
    <parent link="front_arm"/>
    <child link="drum"/>
    <axis xyz="0 0 1"/>
    <limit effort="10" velocity="10"/>
  </joint>

  <link name="front_right_drum">
    <inertial>
      <origin xyz="0 0 0" rpy="0 0 0"/>
      <mass value="1"/>
      <inertia ixx="1" ixy="0" ixz="0" iyy="1" iyz="0" izz="1"/>
    </inertial>
    <visual>
      <origin xyz="-0.000210191 5.63205e-05 -0.31496" rpy="-1.5708 -2.95656e-16 1.48742e-17"/>
      <geometry>
        <mesh filename="file://$(find startup)/urdf/robot/assets/drum.stl"/>
      </geometry>
      <material name="front_right_drum_material">
        <color rgba="0.85098 0.756863 0.866667 1"/>
      </material>
    </visual>
    <collision>
      <origin xyz="-0.000210191 5.63205e-05 -0.31496" rpy="-1.5708 -2.95656e-16 1.48742e-17"/>
      <geometry>
        <mesh filename="file://$(find startup)/urdf/robot/assets/drum.stl"/>
      </geometry>
    </collision>
  </link>
  <joint name="front_right_drum_joint" type="continuous">
    <origin xyz="0.357187 0.0476885 -0.0381" rpy="-7.85046e-17 4.12558e-32 -3.14159"/>
    <parent link="front_arm"/>
    <child link="front_right_drum"/>
    <axis xyz="0 0 1"/>
    <limit effort="10" velocity="10"/>
  </joint>

  <link name="rear_arm">
    <inertial>
      <origin xyz="0 0 0" rpy="0 0 0"/>
      <mass value="1"/>
      <inertia ixx="1" ixy="0" ixz="0" iyy="1" iyz="0" izz="1"/>
    </inertial>
    <visual>
      <origin xyz="0.173038 0 -1.73472e-18" rpy="-1.5708 2.95247e-34 -2.62968e-17"/>
      <geometry>
        <mesh filename="file://$(find startup)/urdf/robot/assets/frame__length_0_40640000000000004_meter.stl"/>
      </geometry>
      <material name="frame__length_0_40640000000000004_meter_5_material">
        <color rgba="0.647059 0.647059 0.647059 1"/>
      </material>
    </visual>
    <collision>
      <origin xyz="0.173038 0 -1.73472e-18" rpy="-1.5708 2.95247e-34 -2.62968e-17"/>
      <geometry>
        <mesh filename="file://$(find startup)/urdf/robot/assets/frame__length_0_40640000000000004_meter.stl"/>
      </geometry>
    </collision>
  </link>
  
  <joint name="rear_arm_joint" type="continuous">
    <origin xyz="3.1225e-17 0.2921 0.0508" rpy="-1.5708 -1.0472 1.5708"/>
    <parent link="frame_assembly"/>
    <child link="rear_arm"/>
    <axis xyz="0 0 -1"/>
    <limit effort="1000" velocity="1000"/>
    <!-- <limit effort="1000" velocity="1000" lower="-2" upper="0.4"/> -->
    <dynamics damping="80.0" friction="700.0" armature="0.01"/>
  </joint>

  <link name="rear_right_drum">
    <inertial>
      <origin xyz="0 0 0" rpy="0 0 0"/>
      <mass value="1"/>
      <inertia ixx="1" ixy="0" ixz="0" iyy="1" iyz="0" izz="1"/>
    </inertial>
    <visual>
      <origin xyz="0 0 0.00254" rpy="-1.5708 -1.08695e-32 -3.82533e-17"/>
      <geometry>
        <mesh filename="file://$(find startup)/urdf/robot/assets/drum.stl"/>
      </geometry>
      <material name="rear_right_drum_material">
        <color rgba="0.85098 0.756863 0.866667 1"/>
      </material>
    </visual>
    <collision>
      <origin xyz="0 0 0.00254" rpy="-1.5708 -1.08695e-32 -3.82533e-17"/>
      <geometry>
        <mesh filename="file://$(find startup)/urdf/robot/assets/drum.stl"/>
      </geometry>
    </collision>
  </link>
  <joint name="rear_right_drum_joint" type="continuous">
    <origin xyz="0.357187 0.0476885 0.0381" rpy="3.90337e-31 5.47109e-32 -3.14159"/>
    <parent link="rear_arm"/>
    <child link="rear_right_drum"/>
    <axis xyz="0 0 1"/>
    <limit effort="10" velocity="10"/>
  </joint>

  <link name="rear_left_drum">
    <inertial>
      <origin xyz="0 0 0" rpy="0 0 0"/>
      <mass value="1"/>
      <inertia ixx="1" ixy="0" ixz="0" iyy="1" iyz="0" izz="1"/>
    </inertial>
    <visual>
      <origin xyz="-0.000210191 5.63205e-05 -0.31496" rpy="-1.5708 -2.95656e-16 -1.35584e-17"/>
      <geometry>
        <mesh filename="file://$(find startup)/urdf/robot/assets/drum.stl"/>
      </geometry>
      <material name="rear_left_drum_material">
        <color rgba="0.85098 0.756863 0.866667 1"/>
      </material>
    </visual>
    <collision>
      <origin xyz="-0.000210191 5.63205e-05 -0.31496" rpy="-1.5708 -2.95656e-16 -1.35584e-17"/>
      <geometry>
        <mesh filename="file://$(find startup)/urdf/robot/assets/drum.stl"/>
      </geometry>
    </collision>
  </link>
  <joint name="rear_left_drum_joint" type="continuous">
    <origin xyz="0.357188 0.0476885 -0.0381" rpy="6.51149e-31 -1.66571e-30 -8.18079e-17"/>
    <parent link="rear_arm"/>
    <child link="rear_left_drum"/>
    <axis xyz="0 0 1"/>
    <limit effort="10" velocity="10"/>
  </joint>
</robot>
